[2024-01-11 17:36:54] [INFO    ] discord.client: logging in using static token
[2024-01-11 17:36:55] [INFO    ] discord.gateway: Shard ID None has connected to Gateway (Session ID: 8d986d0b1ce3e1bf92dc2f37ac8a1d47).
[2024-01-11 17:38:27] [ERROR   ] discord.app_commands.tree: Ignoring exception in command 'warn'
Traceback (most recent call last):
  File "/home/ole/.local/lib/python3.11/site-packages/discord/app_commands/commands.py", line 827, in _do_call
    return await self._callback(self.binding, interaction, **params)  # type: ignore
           ^^^^^^^^^^^^^^^^^^^^^^^^^^^^^^^^^^^^^^^^^^^^^^^^^^^^^^^^^
  File "/home/ole/Dokumente/VscProjekte/DiscordBot/WarnBot/src/cogs/warn.py", line 100, in warn_user
    await interaction.response.send_message(
  File "/home/ole/.local/lib/python3.11/site-packages/discord/interactions.py", line 774, in send_message
    raise InteractionResponded(self._parent)
discord.errors.InteractionResponded: This interaction has already been responded to before

The above exception was the direct cause of the following exception:

Traceback (most recent call last):
  File "/home/ole/.local/lib/python3.11/site-packages/discord/app_commands/tree.py", line 1248, in _call
    await command._invoke_with_namespace(interaction, namespace)
  File "/home/ole/.local/lib/python3.11/site-packages/discord/app_commands/commands.py", line 853, in _invoke_with_namespace
    return await self._do_call(interaction, transformed_values)
           ^^^^^^^^^^^^^^^^^^^^^^^^^^^^^^^^^^^^^^^^^^^^^^^^^^^^
  File "/home/ole/.local/lib/python3.11/site-packages/discord/app_commands/commands.py", line 846, in _do_call
    raise CommandInvokeError(self, e) from e
discord.app_commands.errors.CommandInvokeError: Command 'warn' raised an exception: InteractionResponded: This interaction has already been responded to before
[2024-01-11 17:38:33] [ERROR   ] discord.app_commands.tree: Ignoring exception in command 'warn'
Traceback (most recent call last):
  File "/home/ole/.local/lib/python3.11/site-packages/discord/app_commands/commands.py", line 827, in _do_call
    return await self._callback(self.binding, interaction, **params)  # type: ignore
           ^^^^^^^^^^^^^^^^^^^^^^^^^^^^^^^^^^^^^^^^^^^^^^^^^^^^^^^^^
  File "/home/ole/Dokumente/VscProjekte/DiscordBot/WarnBot/src/cogs/warn.py", line 107, in warn_user
    await interaction.response.send_message(
  File "/home/ole/.local/lib/python3.11/site-packages/discord/interactions.py", line 774, in send_message
    raise InteractionResponded(self._parent)
discord.errors.InteractionResponded: This interaction has already been responded to before

The above exception was the direct cause of the following exception:

Traceback (most recent call last):
  File "/home/ole/.local/lib/python3.11/site-packages/discord/app_commands/tree.py", line 1248, in _call
    await command._invoke_with_namespace(interaction, namespace)
  File "/home/ole/.local/lib/python3.11/site-packages/discord/app_commands/commands.py", line 853, in _invoke_with_namespace
    return await self._do_call(interaction, transformed_values)
           ^^^^^^^^^^^^^^^^^^^^^^^^^^^^^^^^^^^^^^^^^^^^^^^^^^^^
  File "/home/ole/.local/lib/python3.11/site-packages/discord/app_commands/commands.py", line 846, in _do_call
    raise CommandInvokeError(self, e) from e
discord.app_commands.errors.CommandInvokeError: Command 'warn' raised an exception: InteractionResponded: This interaction has already been responded to before
